2020-12-16 17:44:11,865 univmax_conn.py WARNING : No array id specified. Please set array ID using the "set_array_id(array_id)" function.
2020-12-16 17:44:11,865 dellemc_powermax_gatherfacts.py INFO : Got PyU4V Unisphere instance for common lib method access on VMAX
2020-12-16 17:44:11,865 dellemc_powermax_gatherfacts.py INFO : Getting Array List 
2020-12-16 17:46:11,868 rest_requests.py ERROR : The GET request to URL https://10.126.70.19:8443/univmax/restapi/90/system/symmetrix timed-out, but may have been successful. Please check the array. Exception received: HTTPSConnectionPool(host='10.126.70.19', port=8443): Max retries exceeded with url: /univmax/restapi/90/system/symmetrix (Caused by ConnectTimeoutError(<urllib3.connection.HTTPSConnection object at 0x7f994c7e92b0>, 'Connection to 10.126.70.19 timed out. (connect timeout=120)')).
2020-12-16 17:46:11,869 dellemc_powermax_gatherfacts.py ERROR : ('Get Array List for Unisphere host %s failed with error %s', {'type': 'str', 'required': True}, 'Bad or unexpected response from the storage volume backend API: Error get symmetrix. The status code received is None and the message is None.')
2020-12-16 18:05:50,414 univmax_conn.py WARNING : No array id specified. Please set array ID using the "set_array_id(array_id)" function.
2020-12-16 18:05:50,414 dellemc_powermax_gatherfacts.py INFO : Got PyU4V Unisphere instance for common lib method access on VMAX
2020-12-16 18:05:50,415 dellemc_powermax_gatherfacts.py INFO : Getting Array List 
2020-12-16 18:07:50,461 rest_requests.py ERROR : The GET request to URL https://10.126.70.28:8443/univmax/restapi/90/system/symmetrix timed-out, but may have been successful. Please check the array. Exception received: HTTPSConnectionPool(host='10.126.70.28', port=8443): Max retries exceeded with url: /univmax/restapi/90/system/symmetrix (Caused by ConnectTimeoutError(<urllib3.connection.HTTPSConnection object at 0x7fc8935822b0>, 'Connection to 10.126.70.28 timed out. (connect timeout=120)')).
2020-12-16 18:07:50,462 dellemc_powermax_gatherfacts.py ERROR : ('Get Array List for Unisphere host %s failed with error %s', {'type': 'str', 'required': True}, 'Bad or unexpected response from the storage volume backend API: Error get symmetrix. The status code received is None and the message is None.')
2020-12-16 18:41:17,453 univmax_conn.py WARNING : No array id specified. Please set array ID using the "set_array_id(array_id)" function.
2020-12-16 18:41:17,453 dellemc_powermax_gatherfacts.py INFO : Got PyU4V Unisphere instance for common lib method access on VMAX
2020-12-16 18:41:17,454 dellemc_powermax_gatherfacts.py INFO : Getting Array List 
2020-12-16 18:43:17,457 rest_requests.py ERROR : The GET request to URL https://10.126.70.28:8443/univmax/restapi/90/system/symmetrix timed-out, but may have been successful. Please check the array. Exception received: HTTPSConnectionPool(host='10.126.70.28', port=8443): Max retries exceeded with url: /univmax/restapi/90/system/symmetrix (Caused by ConnectTimeoutError(<urllib3.connection.HTTPSConnection object at 0x7f36c1126f60>, 'Connection to 10.126.70.28 timed out. (connect timeout=120)')).
2020-12-16 18:43:17,458 dellemc_powermax_gatherfacts.py ERROR : ('Get Array List for Unisphere host %s failed with error %s', {'type': 'str', 'required': True}, 'Bad or unexpected response from the storage volume backend API: Error get symmetrix. The status code received is None and the message is None.')
2020-12-16 18:44:33,389 univmax_conn.py WARNING : No array id specified. Please set array ID using the "set_array_id(array_id)" function.
2020-12-16 18:44:33,389 dellemc_powermax_gatherfacts.py INFO : Got PyU4V Unisphere instance for common lib method access on VMAX
2020-12-16 18:44:33,389 dellemc_powermax_gatherfacts.py INFO : Getting Array List 
2020-12-16 18:46:33,424 rest_requests.py ERROR : The GET request to URL https://10.126.70.28:8443/univmax/restapi/90/system/symmetrix timed-out, but may have been successful. Please check the array. Exception received: HTTPSConnectionPool(host='10.126.70.28', port=8443): Max retries exceeded with url: /univmax/restapi/90/system/symmetrix (Caused by ConnectTimeoutError(<urllib3.connection.HTTPSConnection object at 0x7f43c8caff60>, 'Connection to 10.126.70.28 timed out. (connect timeout=120)')).
2020-12-16 18:46:33,424 dellemc_powermax_gatherfacts.py ERROR : ('Get Array List for Unisphere host %s failed with error %s', {'type': 'str', 'required': True}, 'Bad or unexpected response from the storage volume backend API: Error get symmetrix. The status code received is None and the message is None.')
2020-12-16 19:00:18,497 univmax_conn.py WARNING : No array id specified. Please set array ID using the "set_array_id(array_id)" function.
2020-12-16 19:00:18,497 dellemc_powermax_gatherfacts.py INFO : Got PyU4V Unisphere instance for common lib method access on VMAX
2020-12-16 19:00:18,498 dellemc_powermax_gatherfacts.py INFO : Getting Array List 
2020-12-16 19:02:18,597 rest_requests.py ERROR : The GET request to URL https://10.126.70.28:8443/univmax/restapi/90/system/symmetrix timed-out, but may have been successful. Please check the array. Exception received: HTTPSConnectionPool(host='10.126.70.28', port=8443): Max retries exceeded with url: /univmax/restapi/90/system/symmetrix (Caused by ConnectTimeoutError(<urllib3.connection.HTTPSConnection object at 0x7f0047f182b0>, 'Connection to 10.126.70.28 timed out. (connect timeout=120)')).
2020-12-16 19:02:18,598 dellemc_powermax_gatherfacts.py ERROR : ('Get Array List for Unisphere host %s failed with error %s', {'type': 'str', 'required': True}, 'Bad or unexpected response from the storage volume backend API: Error get symmetrix. The status code received is None and the message is None.')
2020-12-16 19:20:33,929 dellemc_isilon_gatherfacts.py INFO : Got python SDK instance for provisioning on Isilon 
2020-12-16 19:22:44,306 connectionpool.py WARNING : Retrying (Retry(total=2, connect=None, read=None, redirect=None, status=None)) after connection broken by 'NewConnectionError('<urllib3.connection.HTTPSConnection object at 0x7fb45e544080>: Failed to establish a new connection: [Errno 110] Connection timed out',)': /session/1/session
2020-12-16 19:24:55,377 connectionpool.py WARNING : Retrying (Retry(total=1, connect=None, read=None, redirect=None, status=None)) after connection broken by 'NewConnectionError('<urllib3.connection.HTTPSConnection object at 0x7fb45e544438>: Failed to establish a new connection: [Errno 110] Connection timed out',)': /session/1/session
2020-12-16 19:27:06,449 connectionpool.py WARNING : Retrying (Retry(total=0, connect=None, read=None, redirect=None, status=None)) after connection broken by 'NewConnectionError('<urllib3.connection.HTTPSConnection object at 0x7fb45ea12550>: Failed to establish a new connection: [Errno 110] Connection timed out',)': /session/1/session
2020-12-16 19:29:17,521 dellemc_isilon_gatherfacts.py ERROR : Get Attributes List for Isilon cluster: 192.168.3.11 failed with error: HTTPSConnectionPool(host='192.168.3.11', port=8080): Max retries exceeded with url: /session/1/session (Caused by NewConnectionError('<urllib3.connection.HTTPSConnection object at 0x7fb45ea0b470>: Failed to establish a new connection: [Errno 110] Connection timed out',))
2020-12-16 19:31:08,949 dellemc_isilon_gatherfacts.py INFO : Got python SDK instance for provisioning on Isilon 
2020-12-16 19:33:19,185 connectionpool.py WARNING : Retrying (Retry(total=2, connect=None, read=None, redirect=None, status=None)) after connection broken by 'NewConnectionError('<urllib3.connection.HTTPSConnection object at 0x7f7ac6766048>: Failed to establish a new connection: [Errno 110] Connection timed out',)': /session/1/session
2020-12-16 19:35:30,258 connectionpool.py WARNING : Retrying (Retry(total=1, connect=None, read=None, redirect=None, status=None)) after connection broken by 'NewConnectionError('<urllib3.connection.HTTPSConnection object at 0x7f7ac6766240>: Failed to establish a new connection: [Errno 110] Connection timed out',)': /session/1/session
2020-12-16 19:37:41,329 connectionpool.py WARNING : Retrying (Retry(total=0, connect=None, read=None, redirect=None, status=None)) after connection broken by 'NewConnectionError('<urllib3.connection.HTTPSConnection object at 0x7f7ac67664e0>: Failed to establish a new connection: [Errno 110] Connection timed out',)': /session/1/session
2020-12-16 19:39:52,401 dellemc_isilon_gatherfacts.py ERROR : Get Attributes List for Isilon cluster: 192.168.3.11 failed with error: HTTPSConnectionPool(host='192.168.3.11', port=8080): Max retries exceeded with url: /session/1/session (Caused by NewConnectionError('<urllib3.connection.HTTPSConnection object at 0x7f7ac6774668>: Failed to establish a new connection: [Errno 110] Connection timed out',))
2020-12-16 19:48:14,317 dellemc_isilon_filesystem.py INFO : Got python SDK instance for provisioning on Isilon 
2020-12-16 19:50:25,234 connectionpool.py WARNING : Retrying (Retry(total=2, connect=None, read=None, redirect=None, status=None)) after connection broken by 'NewConnectionError('<urllib3.connection.HTTPSConnection object at 0x7f09e24c0d68>: Failed to establish a new connection: [Errno 110] Connection timed out',)': /session/1/session
2020-12-16 19:52:36,305 connectionpool.py WARNING : Retrying (Retry(total=1, connect=None, read=None, redirect=None, status=None)) after connection broken by 'NewConnectionError('<urllib3.connection.HTTPSConnection object at 0x7f09e24c0f98>: Failed to establish a new connection: [Errno 110] Connection timed out',)': /session/1/session
2020-12-16 19:54:47,377 connectionpool.py WARNING : Retrying (Retry(total=0, connect=None, read=None, redirect=None, status=None)) after connection broken by 'NewConnectionError('<urllib3.connection.HTTPSConnection object at 0x7f09e24d1080>: Failed to establish a new connection: [Errno 110] Connection timed out',)': /session/1/session
2020-12-16 19:56:58,449 dellemc_isilon_filesystem.py ERROR : Failed to get details of Filesystem ifs/globaluni/students/peterParker with error HTTPSConnectionPool(host='192.168.3.11', port=8080): Max retries exceeded with url: /session/1/session (Caused by NewConnectionError('<urllib3.connection.HTTPSConnection object at 0x7f09e24d1550>: Failed to establish a new connection: [Errno 110] Connection timed out',)) 
2020-12-16 19:56:59,484 dellemc_isilon_filesystem.py INFO : Got python SDK instance for provisioning on Isilon 
2020-12-16 19:59:09,521 connectionpool.py WARNING : Retrying (Retry(total=2, connect=None, read=None, redirect=None, status=None)) after connection broken by 'NewConnectionError('<urllib3.connection.HTTPSConnection object at 0x7f68b3f40c18>: Failed to establish a new connection: [Errno 110] Connection timed out',)': /session/1/session
2020-12-16 20:01:20,593 connectionpool.py WARNING : Retrying (Retry(total=1, connect=None, read=None, redirect=None, status=None)) after connection broken by 'NewConnectionError('<urllib3.connection.HTTPSConnection object at 0x7f68b3f40fd0>: Failed to establish a new connection: [Errno 110] Connection timed out',)': /session/1/session
2020-12-16 20:03:31,665 connectionpool.py WARNING : Retrying (Retry(total=0, connect=None, read=None, redirect=None, status=None)) after connection broken by 'NewConnectionError('<urllib3.connection.HTTPSConnection object at 0x7f68b449c668>: Failed to establish a new connection: [Errno 110] Connection timed out',)': /session/1/session
2020-12-16 20:05:42,737 dellemc_isilon_filesystem.py ERROR : Failed to get details of Filesystem ifs/globaluni/students/lukeCage with error HTTPSConnectionPool(host='192.168.3.11', port=8080): Max retries exceeded with url: /session/1/session (Caused by NewConnectionError('<urllib3.connection.HTTPSConnection object at 0x7f68b441b208>: Failed to establish a new connection: [Errno 110] Connection timed out',)) 
2020-12-16 20:05:43,704 dellemc_isilon_filesystem.py INFO : Got python SDK instance for provisioning on Isilon 
2020-12-16 20:07:53,810 connectionpool.py WARNING : Retrying (Retry(total=2, connect=None, read=None, redirect=None, status=None)) after connection broken by 'NewConnectionError('<urllib3.connection.HTTPSConnection object at 0x7f3e1b1ca198>: Failed to establish a new connection: [Errno 110] Connection timed out',)': /session/1/session
2020-12-16 20:10:04,881 connectionpool.py WARNING : Retrying (Retry(total=1, connect=None, read=None, redirect=None, status=None)) after connection broken by 'NewConnectionError('<urllib3.connection.HTTPSConnection object at 0x7f3e1b1ca390>: Failed to establish a new connection: [Errno 110] Connection timed out',)': /session/1/session
2020-12-16 20:12:15,953 connectionpool.py WARNING : Retrying (Retry(total=0, connect=None, read=None, redirect=None, status=None)) after connection broken by 'NewConnectionError('<urllib3.connection.HTTPSConnection object at 0x7f3e1b1ca6d8>: Failed to establish a new connection: [Errno 110] Connection timed out',)': /session/1/session
2020-12-16 20:14:27,025 dellemc_isilon_filesystem.py ERROR : Failed to get details of Filesystem ifs/globaluni/students/natashaRomanoff with error HTTPSConnectionPool(host='192.168.3.11', port=8080): Max retries exceeded with url: /session/1/session (Caused by NewConnectionError('<urllib3.connection.HTTPSConnection object at 0x7f3e1b1d77b8>: Failed to establish a new connection: [Errno 110] Connection timed out',)) 
2020-12-16 20:14:27,941 dellemc_isilon_filesystem.py INFO : Got python SDK instance for provisioning on Isilon 
2020-12-16 20:16:38,098 connectionpool.py WARNING : Retrying (Retry(total=2, connect=None, read=None, redirect=None, status=None)) after connection broken by 'NewConnectionError('<urllib3.connection.HTTPSConnection object at 0x7f4f33e90da0>: Failed to establish a new connection: [Errno 110] Connection timed out',)': /session/1/session
2020-12-16 20:18:49,169 connectionpool.py WARNING : Retrying (Retry(total=1, connect=None, read=None, redirect=None, status=None)) after connection broken by 'NewConnectionError('<urllib3.connection.HTTPSConnection object at 0x7f4f343662e8>: Failed to establish a new connection: [Errno 110] Connection timed out',)': /session/1/session
2020-12-16 20:21:00,241 connectionpool.py WARNING : Retrying (Retry(total=0, connect=None, read=None, redirect=None, status=None)) after connection broken by 'NewConnectionError('<urllib3.connection.HTTPSConnection object at 0x7f4f343665f8>: Failed to establish a new connection: [Errno 110] Connection timed out',)': /session/1/session
2020-12-16 20:23:11,313 dellemc_isilon_filesystem.py ERROR : Failed to get details of Filesystem ifs/globaluni/students/wandaMaximoff with error HTTPSConnectionPool(host='192.168.3.11', port=8080): Max retries exceeded with url: /session/1/session (Caused by NewConnectionError('<urllib3.connection.HTTPSConnection object at 0x7f4f34366c50>: Failed to establish a new connection: [Errno 110] Connection timed out',)) 
2020-12-16 20:23:12,285 dellemc_isilon_filesystem.py INFO : Got python SDK instance for provisioning on Isilon 
2020-12-16 20:25:22,386 connectionpool.py WARNING : Retrying (Retry(total=2, connect=None, read=None, redirect=None, status=None)) after connection broken by 'NewConnectionError('<urllib3.connection.HTTPSConnection object at 0x7faa0d0a9d68>: Failed to establish a new connection: [Errno 110] Connection timed out',)': /session/1/session
2020-12-16 20:27:33,457 connectionpool.py WARNING : Retrying (Retry(total=1, connect=None, read=None, redirect=None, status=None)) after connection broken by 'NewConnectionError('<urllib3.connection.HTTPSConnection object at 0x7faa0d57fbe0>: Failed to establish a new connection: [Errno 110] Connection timed out',)': /session/1/session
2020-12-16 20:29:44,529 connectionpool.py WARNING : Retrying (Retry(total=0, connect=None, read=None, redirect=None, status=None)) after connection broken by 'NewConnectionError('<urllib3.connection.HTTPSConnection object at 0x7faa0d57f780>: Failed to establish a new connection: [Errno 110] Connection timed out',)': /session/1/session
2020-12-16 20:31:55,601 dellemc_isilon_filesystem.py ERROR : Failed to get details of Filesystem ifs/globaluni/students/scottLang with error HTTPSConnectionPool(host='192.168.3.11', port=8080): Max retries exceeded with url: /session/1/session (Caused by NewConnectionError('<urllib3.connection.HTTPSConnection object at 0x7faa0d57fa90>: Failed to establish a new connection: [Errno 110] Connection timed out',)) 
2020-12-16 20:33:20,182 dellemc_isilon_filesystem.py INFO : Got python SDK instance for provisioning on Isilon 
2020-12-16 20:35:30,642 connectionpool.py WARNING : Retrying (Retry(total=2, connect=None, read=None, redirect=None, status=None)) after connection broken by 'NewConnectionError('<urllib3.connection.HTTPSConnection object at 0x7f28ba671be0>: Failed to establish a new connection: [Errno 110] Connection timed out',)': /session/1/session
2020-12-16 20:37:41,713 connectionpool.py WARNING : Retrying (Retry(total=1, connect=None, read=None, redirect=None, status=None)) after connection broken by 'NewConnectionError('<urllib3.connection.HTTPSConnection object at 0x7f28ba671f98>: Failed to establish a new connection: [Errno 110] Connection timed out',)': /session/1/session
2020-12-16 20:39:52,785 connectionpool.py WARNING : Retrying (Retry(total=0, connect=None, read=None, redirect=None, status=None)) after connection broken by 'NewConnectionError('<urllib3.connection.HTTPSConnection object at 0x7f28ba682320>: Failed to establish a new connection: [Errno 110] Connection timed out',)': /session/1/session
2020-12-16 20:42:03,858 dellemc_isilon_filesystem.py ERROR : Failed to get details of Filesystem ifs/globaluni/students/peterParker with error HTTPSConnectionPool(host='192.168.3.11', port=8080): Max retries exceeded with url: /session/1/session (Caused by NewConnectionError('<urllib3.connection.HTTPSConnection object at 0x7f28ba68b3c8>: Failed to establish a new connection: [Errno 110] Connection timed out',)) 
2020-12-16 20:42:04,796 dellemc_isilon_filesystem.py INFO : Got python SDK instance for provisioning on Isilon 
2020-12-16 20:44:14,930 connectionpool.py WARNING : Retrying (Retry(total=2, connect=None, read=None, redirect=None, status=None)) after connection broken by 'NewConnectionError('<urllib3.connection.HTTPSConnection object at 0x7f9334e29198>: Failed to establish a new connection: [Errno 110] Connection timed out',)': /session/1/session
2020-12-16 20:46:26,001 connectionpool.py WARNING : Retrying (Retry(total=1, connect=None, read=None, redirect=None, status=None)) after connection broken by 'NewConnectionError('<urllib3.connection.HTTPSConnection object at 0x7f9334e29390>: Failed to establish a new connection: [Errno 110] Connection timed out',)': /session/1/session
2020-12-16 20:48:37,073 connectionpool.py WARNING : Retrying (Retry(total=0, connect=None, read=None, redirect=None, status=None)) after connection broken by 'NewConnectionError('<urllib3.connection.HTTPSConnection object at 0x7f9334e29630>: Failed to establish a new connection: [Errno 110] Connection timed out',)': /session/1/session
2020-12-16 20:50:48,145 dellemc_isilon_filesystem.py ERROR : Failed to get details of Filesystem ifs/globaluni/students/lukeCage with error HTTPSConnectionPool(host='192.168.3.11', port=8080): Max retries exceeded with url: /session/1/session (Caused by NewConnectionError('<urllib3.connection.HTTPSConnection object at 0x7f9334e367b8>: Failed to establish a new connection: [Errno 110] Connection timed out',)) 
2020-12-16 20:50:49,128 dellemc_isilon_filesystem.py INFO : Got python SDK instance for provisioning on Isilon 
2020-12-16 20:52:59,218 connectionpool.py WARNING : Retrying (Retry(total=2, connect=None, read=None, redirect=None, status=None)) after connection broken by 'NewConnectionError('<urllib3.connection.HTTPSConnection object at 0x7f5b133d0da0>: Failed to establish a new connection: [Errno 110] Connection timed out',)': /session/1/session
2020-12-16 20:55:10,289 connectionpool.py WARNING : Retrying (Retry(total=1, connect=None, read=None, redirect=None, status=None)) after connection broken by 'NewConnectionError('<urllib3.connection.HTTPSConnection object at 0x7f5b138a6ef0>: Failed to establish a new connection: [Errno 110] Connection timed out',)': /session/1/session
2020-12-16 20:57:21,361 connectionpool.py WARNING : Retrying (Retry(total=0, connect=None, read=None, redirect=None, status=None)) after connection broken by 'NewConnectionError('<urllib3.connection.HTTPSConnection object at 0x7f5b138a66a0>: Failed to establish a new connection: [Errno 110] Connection timed out',)': /session/1/session
2020-12-16 20:59:32,434 dellemc_isilon_filesystem.py ERROR : Failed to get details of Filesystem ifs/globaluni/students/natashaRomanoff with error HTTPSConnectionPool(host='192.168.3.11', port=8080): Max retries exceeded with url: /session/1/session (Caused by NewConnectionError('<urllib3.connection.HTTPSConnection object at 0x7f5b138a67f0>: Failed to establish a new connection: [Errno 110] Connection timed out',)) 
2020-12-16 20:59:33,355 dellemc_isilon_filesystem.py INFO : Got python SDK instance for provisioning on Isilon 
2020-12-16 21:01:43,506 connectionpool.py WARNING : Retrying (Retry(total=2, connect=None, read=None, redirect=None, status=None)) after connection broken by 'NewConnectionError('<urllib3.connection.HTTPSConnection object at 0x7f423ab30ba8>: Failed to establish a new connection: [Errno 110] Connection timed out',)': /session/1/session
2020-12-16 21:03:54,577 connectionpool.py WARNING : Retrying (Retry(total=1, connect=None, read=None, redirect=None, status=None)) after connection broken by 'NewConnectionError('<urllib3.connection.HTTPSConnection object at 0x7f423ab30f28>: Failed to establish a new connection: [Errno 110] Connection timed out',)': /session/1/session
2020-12-16 21:06:05,649 connectionpool.py WARNING : Retrying (Retry(total=0, connect=None, read=None, redirect=None, status=None)) after connection broken by 'NewConnectionError('<urllib3.connection.HTTPSConnection object at 0x7f423ab42208>: Failed to establish a new connection: [Errno 110] Connection timed out',)': /session/1/session
2020-12-16 21:08:16,721 dellemc_isilon_filesystem.py ERROR : Failed to get details of Filesystem ifs/globaluni/students/wandaMaximoff with error HTTPSConnectionPool(host='192.168.3.11', port=8080): Max retries exceeded with url: /session/1/session (Caused by NewConnectionError('<urllib3.connection.HTTPSConnection object at 0x7f423ab4a390>: Failed to establish a new connection: [Errno 110] Connection timed out',)) 
2020-12-16 21:08:17,672 dellemc_isilon_filesystem.py INFO : Got python SDK instance for provisioning on Isilon 
2020-12-16 21:10:27,794 connectionpool.py WARNING : Retrying (Retry(total=2, connect=None, read=None, redirect=None, status=None)) after connection broken by 'NewConnectionError('<urllib3.connection.HTTPSConnection object at 0x7fc4aa81add8>: Failed to establish a new connection: [Errno 110] Connection timed out',)': /session/1/session
2020-12-16 21:12:38,865 connectionpool.py WARNING : Retrying (Retry(total=1, connect=None, read=None, redirect=None, status=None)) after connection broken by 'NewConnectionError('<urllib3.connection.HTTPSConnection object at 0x7fc4aacf06d8>: Failed to establish a new connection: [Errno 110] Connection timed out',)': /session/1/session
2020-12-16 21:14:49,937 connectionpool.py WARNING : Retrying (Retry(total=0, connect=None, read=None, redirect=None, status=None)) after connection broken by 'NewConnectionError('<urllib3.connection.HTTPSConnection object at 0x7fc4aacf0a20>: Failed to establish a new connection: [Errno 110] Connection timed out',)': /session/1/session
2020-12-16 21:17:01,009 dellemc_isilon_filesystem.py ERROR : Failed to get details of Filesystem ifs/globaluni/students/scottLang with error HTTPSConnectionPool(host='192.168.3.11', port=8080): Max retries exceeded with url: /session/1/session (Caused by NewConnectionError('<urllib3.connection.HTTPSConnection object at 0x7fc4aacf0b00>: Failed to establish a new connection: [Errno 110] Connection timed out',)) 
2020-12-16 21:20:39,229 dellemc_isilon_gatherfacts.py INFO : Got python SDK instance for provisioning on Isilon 
2020-12-16 21:22:49,169 connectionpool.py WARNING : Retrying (Retry(total=2, connect=None, read=None, redirect=None, status=None)) after connection broken by 'NewConnectionError('<urllib3.connection.HTTPSConnection object at 0x7f73511a91d0>: Failed to establish a new connection: [Errno 110] Connection timed out',)': /session/1/session
2020-12-16 21:25:00,242 connectionpool.py WARNING : Retrying (Retry(total=1, connect=None, read=None, redirect=None, status=None)) after connection broken by 'NewConnectionError('<urllib3.connection.HTTPSConnection object at 0x7f73511a92e8>: Failed to establish a new connection: [Errno 110] Connection timed out',)': /session/1/session
2020-12-16 21:27:11,313 connectionpool.py WARNING : Retrying (Retry(total=0, connect=None, read=None, redirect=None, status=None)) after connection broken by 'NewConnectionError('<urllib3.connection.HTTPSConnection object at 0x7f73511a96a0>: Failed to establish a new connection: [Errno 110] Connection timed out',)': /session/1/session
2020-12-16 21:29:22,386 dellemc_isilon_gatherfacts.py ERROR : Get Attributes List for Isilon cluster: 192.168.3.11 failed with error: HTTPSConnectionPool(host='192.168.3.11', port=8080): Max retries exceeded with url: /session/1/session (Caused by NewConnectionError('<urllib3.connection.HTTPSConnection object at 0x7f73511a9668>: Failed to establish a new connection: [Errno 110] Connection timed out',))
2020-12-16 21:30:19,072 dellemc_isilon_gatherfacts.py INFO : Got python SDK instance for provisioning on Isilon 
2020-12-16 21:32:28,753 connectionpool.py WARNING : Retrying (Retry(total=2, connect=None, read=None, redirect=None, status=None)) after connection broken by 'NewConnectionError('<urllib3.connection.HTTPSConnection object at 0x7f6d0f4591d0>: Failed to establish a new connection: [Errno 110] Connection timed out',)': /session/1/session
2020-12-16 21:34:39,826 connectionpool.py WARNING : Retrying (Retry(total=1, connect=None, read=None, redirect=None, status=None)) after connection broken by 'NewConnectionError('<urllib3.connection.HTTPSConnection object at 0x7f6d0f4592e8>: Failed to establish a new connection: [Errno 110] Connection timed out',)': /session/1/session
2020-12-16 21:36:50,897 connectionpool.py WARNING : Retrying (Retry(total=0, connect=None, read=None, redirect=None, status=None)) after connection broken by 'NewConnectionError('<urllib3.connection.HTTPSConnection object at 0x7f6d0f459668>: Failed to establish a new connection: [Errno 110] Connection timed out',)': /session/1/session
2020-12-16 21:39:01,969 dellemc_isilon_gatherfacts.py ERROR : Get Attributes List for Isilon cluster: 192.168.3.11 failed with error: HTTPSConnectionPool(host='192.168.3.11', port=8080): Max retries exceeded with url: /session/1/session (Caused by NewConnectionError('<urllib3.connection.HTTPSConnection object at 0x7f6d0f4597f0>: Failed to establish a new connection: [Errno 110] Connection timed out',))
2020-12-16 21:41:25,656 dellemc_isilon_gatherfacts.py INFO : Got python SDK instance for provisioning on Isilon 
2020-12-16 21:43:36,402 connectionpool.py WARNING : Retrying (Retry(total=2, connect=None, read=None, redirect=None, status=None)) after connection broken by 'NewConnectionError('<urllib3.connection.HTTPSConnection object at 0x7f44f44a5dd8>: Failed to establish a new connection: [Errno 110] Connection timed out',)': /session/1/session
2020-12-16 21:45:47,473 connectionpool.py WARNING : Retrying (Retry(total=1, connect=None, read=None, redirect=None, status=None)) after connection broken by 'NewConnectionError('<urllib3.connection.HTTPSConnection object at 0x7f44f44ad1d0>: Failed to establish a new connection: [Errno 110] Connection timed out',)': /session/1/session
2020-12-16 21:47:58,545 connectionpool.py WARNING : Retrying (Retry(total=0, connect=None, read=None, redirect=None, status=None)) after connection broken by 'NewConnectionError('<urllib3.connection.HTTPSConnection object at 0x7f44f44ad470>: Failed to establish a new connection: [Errno 110] Connection timed out',)': /session/1/session
2020-12-16 21:50:09,618 dellemc_isilon_gatherfacts.py ERROR : Get Attributes List for Isilon cluster: 192.168.3.11 failed with error: HTTPSConnectionPool(host='192.168.3.11', port=8080): Max retries exceeded with url: /session/1/session (Caused by NewConnectionError('<urllib3.connection.HTTPSConnection object at 0x7f44f44b95f8>: Failed to establish a new connection: [Errno 110] Connection timed out',))
2020-12-16 21:52:02,108 dellemc_isilon_gatherfacts.py INFO : Got python SDK instance for provisioning on Isilon 
2020-12-16 21:54:11,282 connectionpool.py WARNING : Retrying (Retry(total=2, connect=None, read=None, redirect=None, status=None)) after connection broken by 'NewConnectionError('<urllib3.connection.HTTPSConnection object at 0x7f2c965c1128>: Failed to establish a new connection: [Errno 110] Connection timed out',)': /session/1/session
2020-12-16 21:56:22,354 connectionpool.py WARNING : Retrying (Retry(total=1, connect=None, read=None, redirect=None, status=None)) after connection broken by 'NewConnectionError('<urllib3.connection.HTTPSConnection object at 0x7f2c965c1320>: Failed to establish a new connection: [Errno 110] Connection timed out',)': /session/1/session
2020-12-16 21:58:33,425 connectionpool.py WARNING : Retrying (Retry(total=0, connect=None, read=None, redirect=None, status=None)) after connection broken by 'NewConnectionError('<urllib3.connection.HTTPSConnection object at 0x7f2c965c1710>: Failed to establish a new connection: [Errno 110] Connection timed out',)': /session/1/session
2020-12-16 22:00:44,498 dellemc_isilon_gatherfacts.py ERROR : Get Attributes List for Isilon cluster: 192.168.3.11 failed with error: HTTPSConnectionPool(host='192.168.3.11', port=8080): Max retries exceeded with url: /session/1/session (Caused by NewConnectionError('<urllib3.connection.HTTPSConnection object at 0x7f2c965c15f8>: Failed to establish a new connection: [Errno 110] Connection timed out',))
2020-12-16 22:01:41,140 dellemc_isilon_gatherfacts.py INFO : Got python SDK instance for provisioning on Isilon 
2020-12-16 22:03:50,866 connectionpool.py WARNING : Retrying (Retry(total=2, connect=None, read=None, redirect=None, status=None)) after connection broken by 'NewConnectionError('<urllib3.connection.HTTPSConnection object at 0x7f5998f0bda0>: Failed to establish a new connection: [Errno 110] Connection timed out',)': /session/1/session
2020-12-16 22:06:01,938 connectionpool.py WARNING : Retrying (Retry(total=1, connect=None, read=None, redirect=None, status=None)) after connection broken by 'NewConnectionError('<urllib3.connection.HTTPSConnection object at 0x7f5998f13198>: Failed to establish a new connection: [Errno 110] Connection timed out',)': /session/1/session
2020-12-16 22:08:13,009 connectionpool.py WARNING : Retrying (Retry(total=0, connect=None, read=None, redirect=None, status=None)) after connection broken by 'NewConnectionError('<urllib3.connection.HTTPSConnection object at 0x7f5998f13438>: Failed to establish a new connection: [Errno 110] Connection timed out',)': /session/1/session
2020-12-16 22:10:24,081 dellemc_isilon_gatherfacts.py ERROR : Get Attributes List for Isilon cluster: 192.168.3.11 failed with error: HTTPSConnectionPool(host='192.168.3.11', port=8080): Max retries exceeded with url: /session/1/session (Caused by NewConnectionError('<urllib3.connection.HTTPSConnection object at 0x7f5998f1f5c0>: Failed to establish a new connection: [Errno 110] Connection timed out',))
2020-12-16 22:36:41,457 dellemc_unity_gatherfacts.py INFO : Got the unity instance for provisioning on Unity
2020-12-16 22:36:41,457 dellemc_unity_gatherfacts.py INFO : Getting array details 
2020-12-16 22:36:48,242 dellemc_unity_gatherfacts.py ERROR : Get array details from unity array failed with error HTTPSConnectionPool(host='10.10.4.9', port=443): Max retries exceeded with url: /api/types/basicSystemInfo?compact=True&fields=attributes.description,attributes.displayValue,attributes.initialValue,attributes.name,attributes.type,description,documentation,name,type (Caused by NewConnectionError('<urllib3.connection.HTTPSConnection object at 0x7f1204e69dd8>: Failed to establish a new connection: [Errno 113] No route to host',))
2020-12-16 22:38:04,482 dellemc_unity_gatherfacts.py INFO : Got the unity instance for provisioning on Unity
2020-12-16 22:38:04,482 dellemc_unity_gatherfacts.py INFO : Getting array details 
2020-12-16 22:38:11,346 dellemc_unity_gatherfacts.py ERROR : Get array details from unity array failed with error HTTPSConnectionPool(host='10.10.4.9', port=443): Max retries exceeded with url: /api/types/basicSystemInfo?compact=True&fields=attributes.description,attributes.displayValue,attributes.initialValue,attributes.name,attributes.type,description,documentation,name,type (Caused by NewConnectionError('<urllib3.connection.HTTPSConnection object at 0x7f9eefaead30>: Failed to establish a new connection: [Errno 113] No route to host',))
